<?xml version="1.0" encoding="UTF-8"?>
<testng-results skipped="1" failed="3" ignored="0" total="6" passed="2">
  <reporter-output>
  </reporter-output>
  <suite name="Innovation Agile Tests" duration-ms="525" started-at="2019-12-11T05:01:59Z" finished-at="2019-12-11T05:02:00Z">
    <groups>
    </groups>
    <test name="All" duration-ms="525" started-at="2019-12-11T05:01:59Z" finished-at="2019-12-11T05:02:00Z">
      <class name="tests.LoginTest">
        <test-method status="FAIL" signature="test1()[pri:0, instance:tests.LoginTest@3a03464]" name="test1" duration-ms="40" started-at="2019-12-11T05:02:00Z" finished-at="2019-12-11T05:02:00Z">
          <exception class="java.lang.AssertionError">
            <message>
              <![CDATA[expected [2] but found [1]]]>
            </message>
            <full-stacktrace>
              <![CDATA[java.lang.AssertionError: expected [2] but found [1]
at org.testng.Assert.fail(Assert.java:96)
at org.testng.Assert.failNotEquals(Assert.java:776)
at org.testng.Assert.assertEqualsImpl(Assert.java:137)
at org.testng.Assert.assertEquals(Assert.java:118)
at org.testng.Assert.assertEquals(Assert.java:652)
at org.testng.Assert.assertEquals(Assert.java:662)
at tests.LoginTest.test1(LoginTest.java:10)
at sun.reflect.NativeMethodAccessorImpl.invoke0(Native Method)
at sun.reflect.NativeMethodAccessorImpl.invoke(NativeMethodAccessorImpl.java:62)
at sun.reflect.DelegatingMethodAccessorImpl.invoke(DelegatingMethodAccessorImpl.java:43)
at java.lang.reflect.Method.invoke(Method.java:498)
at org.testng.internal.MethodInvocationHelper.invokeMethod(MethodInvocationHelper.java:124)
at org.testng.internal.Invoker.invokeMethod(Invoker.java:583)
at org.testng.internal.Invoker.invokeTestMethod(Invoker.java:719)
at org.testng.internal.Invoker.invokeTestMethods(Invoker.java:989)
at org.testng.internal.TestMethodWorker.invokeTestMethods(TestMethodWorker.java:125)
at org.testng.internal.TestMethodWorker.run(TestMethodWorker.java:109)
at org.testng.TestRunner.privateRun(TestRunner.java:648)
at org.testng.TestRunner.run(TestRunner.java:505)
at org.testng.SuiteRunner.runTest(SuiteRunner.java:455)
at org.testng.SuiteRunner.runSequentially(SuiteRunner.java:450)
at org.testng.SuiteRunner.privateRun(SuiteRunner.java:415)
at org.testng.SuiteRunner.run(SuiteRunner.java:364)
at org.testng.SuiteRunnerWorker.runSuite(SuiteRunnerWorker.java:52)
at org.testng.SuiteRunnerWorker.run(SuiteRunnerWorker.java:84)
at org.testng.TestNG.runSuitesSequentially(TestNG.java:1208)
at org.testng.TestNG.runSuitesLocally(TestNG.java:1137)
at org.testng.TestNG.runSuites(TestNG.java:1049)
at org.testng.TestNG.run(TestNG.java:1017)
at org.apache.maven.surefire.testng.TestNGExecutor.run(TestNGExecutor.java:283)
at org.apache.maven.surefire.testng.TestNGXmlTestSuite.execute(TestNGXmlTestSuite.java:75)
at org.apache.maven.surefire.testng.TestNGProvider.invoke(TestNGProvider.java:120)
at org.apache.maven.surefire.booter.ForkedBooter.invokeProviderInSameClassLoader(ForkedBooter.java:384)
at org.apache.maven.surefire.booter.ForkedBooter.runSuitesInProcess(ForkedBooter.java:345)
at org.apache.maven.surefire.booter.ForkedBooter.execute(ForkedBooter.java:126)
at org.apache.maven.surefire.booter.ForkedBooter.main(ForkedBooter.java:418)
]]>
            </full-stacktrace>
          </exception> <!-- java.lang.AssertionError -->
          <reporter-output>
          </reporter-output>
        </test-method> <!-- test1 -->
        <test-method status="FAIL" signature="test2()[pri:0, instance:tests.LoginTest@3a03464]" name="test2" duration-ms="1" started-at="2019-12-11T05:02:00Z" finished-at="2019-12-11T05:02:00Z">
          <exception class="java.lang.AssertionError">
            <message>
              <![CDATA[expected [2] but found [1]]]>
            </message>
            <full-stacktrace>
              <![CDATA[java.lang.AssertionError: expected [2] but found [1]
at org.testng.Assert.fail(Assert.java:96)
at org.testng.Assert.failNotEquals(Assert.java:776)
at org.testng.Assert.assertEqualsImpl(Assert.java:137)
at org.testng.Assert.assertEquals(Assert.java:118)
at org.testng.Assert.assertEquals(Assert.java:652)
at org.testng.Assert.assertEquals(Assert.java:662)
at tests.LoginTest.test2(LoginTest.java:15)
at sun.reflect.NativeMethodAccessorImpl.invoke0(Native Method)
at sun.reflect.NativeMethodAccessorImpl.invoke(NativeMethodAccessorImpl.java:62)
at sun.reflect.DelegatingMethodAccessorImpl.invoke(DelegatingMethodAccessorImpl.java:43)
at java.lang.reflect.Method.invoke(Method.java:498)
at org.testng.internal.MethodInvocationHelper.invokeMethod(MethodInvocationHelper.java:124)
at org.testng.internal.Invoker.invokeMethod(Invoker.java:583)
at org.testng.internal.Invoker.invokeTestMethod(Invoker.java:719)
at org.testng.internal.Invoker.invokeTestMethods(Invoker.java:989)
at org.testng.internal.TestMethodWorker.invokeTestMethods(TestMethodWorker.java:125)
at org.testng.internal.TestMethodWorker.run(TestMethodWorker.java:109)
at org.testng.TestRunner.privateRun(TestRunner.java:648)
at org.testng.TestRunner.run(TestRunner.java:505)
at org.testng.SuiteRunner.runTest(SuiteRunner.java:455)
at org.testng.SuiteRunner.runSequentially(SuiteRunner.java:450)
at org.testng.SuiteRunner.privateRun(SuiteRunner.java:415)
at org.testng.SuiteRunner.run(SuiteRunner.java:364)
at org.testng.SuiteRunnerWorker.runSuite(SuiteRunnerWorker.java:52)
at org.testng.SuiteRunnerWorker.run(SuiteRunnerWorker.java:84)
at org.testng.TestNG.runSuitesSequentially(TestNG.java:1208)
at org.testng.TestNG.runSuitesLocally(TestNG.java:1137)
at org.testng.TestNG.runSuites(TestNG.java:1049)
at org.testng.TestNG.run(TestNG.java:1017)
at org.apache.maven.surefire.testng.TestNGExecutor.run(TestNGExecutor.java:283)
at org.apache.maven.surefire.testng.TestNGXmlTestSuite.execute(TestNGXmlTestSuite.java:75)
at org.apache.maven.surefire.testng.TestNGProvider.invoke(TestNGProvider.java:120)
at org.apache.maven.surefire.booter.ForkedBooter.invokeProviderInSameClassLoader(ForkedBooter.java:384)
at org.apache.maven.surefire.booter.ForkedBooter.runSuitesInProcess(ForkedBooter.java:345)
at org.apache.maven.surefire.booter.ForkedBooter.execute(ForkedBooter.java:126)
at org.apache.maven.surefire.booter.ForkedBooter.main(ForkedBooter.java:418)
]]>
            </full-stacktrace>
          </exception> <!-- java.lang.AssertionError -->
          <reporter-output>
          </reporter-output>
        </test-method> <!-- test2 -->
        <test-method status="FAIL" signature="test3()[pri:0, instance:tests.LoginTest@3a03464]" name="test3" duration-ms="0" started-at="2019-12-11T05:02:00Z" finished-at="2019-12-11T05:02:00Z">
          <exception class="java.lang.AssertionError">
            <message>
              <![CDATA[expected [2] but found [1]]]>
            </message>
            <full-stacktrace>
              <![CDATA[java.lang.AssertionError: expected [2] but found [1]
at org.testng.Assert.fail(Assert.java:96)
at org.testng.Assert.failNotEquals(Assert.java:776)
at org.testng.Assert.assertEqualsImpl(Assert.java:137)
at org.testng.Assert.assertEquals(Assert.java:118)
at org.testng.Assert.assertEquals(Assert.java:652)
at org.testng.Assert.assertEquals(Assert.java:662)
at tests.LoginTest.test3(LoginTest.java:21)
at sun.reflect.NativeMethodAccessorImpl.invoke0(Native Method)
at sun.reflect.NativeMethodAccessorImpl.invoke(NativeMethodAccessorImpl.java:62)
at sun.reflect.DelegatingMethodAccessorImpl.invoke(DelegatingMethodAccessorImpl.java:43)
at java.lang.reflect.Method.invoke(Method.java:498)
at org.testng.internal.MethodInvocationHelper.invokeMethod(MethodInvocationHelper.java:124)
at org.testng.internal.Invoker.invokeMethod(Invoker.java:583)
at org.testng.internal.Invoker.invokeTestMethod(Invoker.java:719)
at org.testng.internal.Invoker.invokeTestMethods(Invoker.java:989)
at org.testng.internal.TestMethodWorker.invokeTestMethods(TestMethodWorker.java:125)
at org.testng.internal.TestMethodWorker.run(TestMethodWorker.java:109)
at org.testng.TestRunner.privateRun(TestRunner.java:648)
at org.testng.TestRunner.run(TestRunner.java:505)
at org.testng.SuiteRunner.runTest(SuiteRunner.java:455)
at org.testng.SuiteRunner.runSequentially(SuiteRunner.java:450)
at org.testng.SuiteRunner.privateRun(SuiteRunner.java:415)
at org.testng.SuiteRunner.run(SuiteRunner.java:364)
at org.testng.SuiteRunnerWorker.runSuite(SuiteRunnerWorker.java:52)
at org.testng.SuiteRunnerWorker.run(SuiteRunnerWorker.java:84)
at org.testng.TestNG.runSuitesSequentially(TestNG.java:1208)
at org.testng.TestNG.runSuitesLocally(TestNG.java:1137)
at org.testng.TestNG.runSuites(TestNG.java:1049)
at org.testng.TestNG.run(TestNG.java:1017)
at org.apache.maven.surefire.testng.TestNGExecutor.run(TestNGExecutor.java:283)
at org.apache.maven.surefire.testng.TestNGXmlTestSuite.execute(TestNGXmlTestSuite.java:75)
at org.apache.maven.surefire.testng.TestNGProvider.invoke(TestNGProvider.java:120)
at org.apache.maven.surefire.booter.ForkedBooter.invokeProviderInSameClassLoader(ForkedBooter.java:384)
at org.apache.maven.surefire.booter.ForkedBooter.runSuitesInProcess(ForkedBooter.java:345)
at org.apache.maven.surefire.booter.ForkedBooter.execute(ForkedBooter.java:126)
at org.apache.maven.surefire.booter.ForkedBooter.main(ForkedBooter.java:418)
]]>
            </full-stacktrace>
          </exception> <!-- java.lang.AssertionError -->
          <reporter-output>
          </reporter-output>
        </test-method> <!-- test3 -->
      </class> <!-- tests.LoginTest -->
      <class name="tests.SignOutTest">
        <test-method status="SKIP" signature="test10()[pri:0, instance:tests.SignOutTest@2d3fcdbd]" name="test10" duration-ms="0" started-at="2019-12-11T05:02:00Z" finished-at="2019-12-11T05:02:00Z">
          <exception class="org.testng.SkipException">
            <message>
              <![CDATA[This Test Case is skipped, because it found a falut]]>
            </message>
            <full-stacktrace>
              <![CDATA[org.testng.SkipException: This Test Case is skipped, because it found a falut
at tests.SignOutTest.test10(SignOutTest.java:10)
at sun.reflect.NativeMethodAccessorImpl.invoke0(Native Method)
at sun.reflect.NativeMethodAccessorImpl.invoke(NativeMethodAccessorImpl.java:62)
at sun.reflect.DelegatingMethodAccessorImpl.invoke(DelegatingMethodAccessorImpl.java:43)
at java.lang.reflect.Method.invoke(Method.java:498)
at org.testng.internal.MethodInvocationHelper.invokeMethod(MethodInvocationHelper.java:124)
at org.testng.internal.Invoker.invokeMethod(Invoker.java:583)
at org.testng.internal.Invoker.invokeTestMethod(Invoker.java:719)
at org.testng.internal.Invoker.invokeTestMethods(Invoker.java:989)
at org.testng.internal.TestMethodWorker.invokeTestMethods(TestMethodWorker.java:125)
at org.testng.internal.TestMethodWorker.run(TestMethodWorker.java:109)
at org.testng.TestRunner.privateRun(TestRunner.java:648)
at org.testng.TestRunner.run(TestRunner.java:505)
at org.testng.SuiteRunner.runTest(SuiteRunner.java:455)
at org.testng.SuiteRunner.runSequentially(SuiteRunner.java:450)
at org.testng.SuiteRunner.privateRun(SuiteRunner.java:415)
at org.testng.SuiteRunner.run(SuiteRunner.java:364)
at org.testng.SuiteRunnerWorker.runSuite(SuiteRunnerWorker.java:52)
at org.testng.SuiteRunnerWorker.run(SuiteRunnerWorker.java:84)
at org.testng.TestNG.runSuitesSequentially(TestNG.java:1208)
at org.testng.TestNG.runSuitesLocally(TestNG.java:1137)
at org.testng.TestNG.runSuites(TestNG.java:1049)
at org.testng.TestNG.run(TestNG.java:1017)
at org.apache.maven.surefire.testng.TestNGExecutor.run(TestNGExecutor.java:283)
at org.apache.maven.surefire.testng.TestNGXmlTestSuite.execute(TestNGXmlTestSuite.java:75)
at org.apache.maven.surefire.testng.TestNGProvider.invoke(TestNGProvider.java:120)
at org.apache.maven.surefire.booter.ForkedBooter.invokeProviderInSameClassLoader(ForkedBooter.java:384)
at org.apache.maven.surefire.booter.ForkedBooter.runSuitesInProcess(ForkedBooter.java:345)
at org.apache.maven.surefire.booter.ForkedBooter.execute(ForkedBooter.java:126)
at org.apache.maven.surefire.booter.ForkedBooter.main(ForkedBooter.java:418)
]]>
            </full-stacktrace>
          </exception> <!-- org.testng.SkipException -->
          <reporter-output>
          </reporter-output>
        </test-method> <!-- test10 -->
        <test-method status="PASS" signature="test20()[pri:0, instance:tests.SignOutTest@2d3fcdbd]" name="test20" duration-ms="1" started-at="2019-12-11T05:02:00Z" finished-at="2019-12-11T05:02:00Z">
          <reporter-output>
          </reporter-output>
        </test-method> <!-- test20 -->
        <test-method status="PASS" signature="test30()[pri:0, instance:tests.SignOutTest@2d3fcdbd]" name="test30" duration-ms="1" started-at="2019-12-11T05:02:00Z" finished-at="2019-12-11T05:02:00Z">
          <reporter-output>
          </reporter-output>
        </test-method> <!-- test30 -->
      </class> <!-- tests.SignOutTest -->
    </test> <!-- All -->
  </suite> <!-- Innovation Agile Tests -->
</testng-results>
